{"errorMessage": "An error occurred (AccessDenied) when calling the GetObject operation: User: arn:aws:sts::762233767492:assumed-role/ScamVanguardLambdaRole/ScamVanguardContactForwarder is not authorized to perform: s3:ListBucket on resource: \"arn:aws:s3:::scamvanguard-email-attachments-9b4aca5c\" because no identity-based policy allows the s3:ListBucket action", "errorType": "ClientError", "requestId": "d6d1ea38-2abb-4366-b105-93d29e5fafb0", "stackTrace": ["  File \"/var/task/forward_contact.py\", line 40, in handler\n    obj = s3.get_object(Bucket=BUCKET, Key=s3_key)\n", "  File \"/var/lang/lib/python3.13/site-packages/botocore/client.py\", line 602, in _api_call\n    return self._make_api_call(operation_name, kwargs)\n", "  File \"/var/lang/lib/python3.13/site-packages/botocore/context.py\", line 123, in wrapper\n    return func(*args, **kwargs)\n", "  File \"/var/lang/lib/python3.13/site-packages/botocore/client.py\", line 1078, in _make_api_call\n    raise error_class(parsed_response, operation_name)\n"]}